Workbook

Sheet Assumptions
A1: mTBI Screening Tool — Financial Model — Assumptions
A2: Single source of truth. Every other tab references this one. Edit only blue (input) or orange (provisional) cells. Set unused tier/role/capex slots to 0 — formulas adapt automatically.
A4: Year | C4: Y1 | D4: Y2 | E4: Y3 | F4: Y4 | G4: Y5 | H4: Y6 | I4: Y7
A5: Period number | C5: 1 | D5: 2 | E5: 3 | F5: 4 | G5: 5 | H5: 6 | I5: 7 | L5: (driver)
A6: Calendar year | C6: 2026 | D6: 2027 | E6: 2028 | F6: 2029 | G6: 2030 | H6: 2031 | I6: 2032
A7: Phase | C7: 1 | D7: 1 | E7: 2 | F7: 2 | G7: 3 | H7: 3 | I7: 3 | L7: (driver) | M7: 1 = research validation, 2 = first commercial, 3 = scale-up
A9: 0. SANITY CHECKS
A10: Total headsets = 3 × inst + parent | C10: =IF(C15=$B$26*C28+C29, "OK", "FAIL") -> OK | D10: =IF(D15=$B$26*D28+D29, "OK", "FAIL") -> OK | E10: =IF(E15=$B$26*E28+E29, "OK", "FAIL") -> OK | F10: =IF(F15=$B$26*F28+F29, "OK", "FAIL") -> OK | G10: =IF(G15=$B$26*G28+G29, "OK", "FAIL") -> OK | H10: =IF(H15=$B$26*H28+H29, "OK", "FAIL") -> OK | I10: =IF(I15=$B$26*I28+I29, "OK", "FAIL") -> OK | M10: Should display OK across the row (row 15 = $B$26·row28 + row29)
A11: Cash never below buffer | B11: =IF(MIN('Cash flow'!C39:I39) >= $B$127, "OK", "BREACH") -> OK | M11: From Cash flow tab — checks all 9 closing-cash years
A12: Balance sheet balances | B12: =IF(SUMPRODUCT(--(ABS('Balance sheet'!C34:K34)<1))=9, "OK", "FAIL") -> OK | M12: From Balance sheet tab — sum of absolute differences
A14: 1. ADOPTION RAMP (derived from GTM channel mix, §3)
A15: Total headsets sold per year (derived) | C15: =$B$26*C28 + C29 -> 0 | D15: =$B$26*D28 + D29 -> 0 | E15: =$B$26*E28 + E29 -> 90 | F15: =$B$26*F28 + F29 -> 270 | G15: =$B$26*G28 + G29 -> 1491 | H15: =$B$26*H28 + H29 -> 3154 | I15: =$B$26*I28 + I29 -> 7575 | L15: headsets | M15: = 3 × institutional buyers + parent buyers (rows 28–29)
A16: Annual subscription churn | B16: 0.1 | L16: % per year | M16: ch.9 §9.4 indicative; applied to start-of-year base
A17: Active headset subscriptions (end of year) | C17: =INDEX($C$28:$K$28, 1, MAX(C5 - Scenarios!$B$26, MIN(C5, 3))) * $B$26 * Scenarios!$B$20 * $B$33 + OFFSET(C17, 0, -1) * (1 - $B$16 * Scenarios!$B$22) -> 0 | D17: =INDEX($C$28:$K$28, 1, MAX(D5 - Scenarios!$B$26, MIN(D5, 3))) * $B$26 * Scenarios!$B$20 * $B$33 + OFFSET(D17, 0, -1) * (1 - $B$16 * Scenarios!$B$22) -> 0 | E17: =INDEX($C$28:$K$28, 1, MAX(E5 - Scenarios!$B$26, MIN(E5, 3))) * $B$26 * Scenarios!$B$20 * $B$33 + OFFSET(E17, 0, -1) * (1 - $B$16 * Scenarios!$B$22) -> 90 | F17: =INDEX($C$28:$K$28, 1, MAX(F5 - Scenarios!$B$26, MIN(F5, 3))) * $B$26 * Scenarios!$B$20 * $B$33 + OFFSET(F17, 0, -1) * (1 - $B$16 * Scenarios!$B$22) -> 351 | G17: =INDEX($C$28:$K$28, 1, MAX(G5 - Scenarios!$B$26, MIN(G5, 3))) * $B$26 * Scenarios!$B$20 * $B$33 + OFFSET(G17, 0, -1) * (1 - $B$16 * Scenarios!$B$22) -> 765.9 | H17: =INDEX($C$28:$K$28, 1, MAX(H5 - Scenarios!$B$26, MIN(H5, 3))) * $B$26 * Scenarios!$B$20 * $B$33 + OFFSET(H17, 0, -1) * (1 - $B$16 * Scenarios!$B$22) -> 1889.31 | I17: =INDEX($C$28:$K$28, 1, MAX(I5 - Scenarios!$B$26, MIN(I5, 3))) * $B$26 * Scenarios!$B$20 * $B$33 + OFFSET(I17, 0, -1) * (1 - $B$16 * Scenarios!$B$22) -> 3950.379 | L17: subs | M17: prior × (1 − churn) + institutional buyers × headsets/inst × attach × adoption
A18: Average headset subscriptions (year) | C18: =(C17 + OFFSET(C17, 0, -1)) / 2 -> 0 | D18: =(D17 + OFFSET(D17, 0, -1)) / 2 -> 0 | E18: =(E17 + OFFSET(E17, 0, -1)) / 2 -> 45 | F18: =(F17 + OFFSET(F17, 0, -1)) / 2 -> 220.5 | G18: =(G17 + OFFSET(G17, 0, -1)) / 2 -> 558.45 | H18: =(H17 + OFFSET(H17, 0, -1)) / 2 -> 1327.605 | I18: =(I17 + OFFSET(I17, 0, -1)) / 2 -> 2919.8445 | L18: subs | M18: (start + end) / 2; drives subscription revenue
A19: Cumulative headsets sold (end of year) | C19: =INDEX($C$15:$K$15, 1, MAX(C5 - Scenarios!$B$26, MIN(C5, 3))) * Scenarios!$B$20 + OFFSET(C19, 0, -1) -> 0 | D19: =INDEX($C$15:$K$15, 1, MAX(D5 - Scenarios!$B$26, MIN(D5, 3))) * Scenarios!$B$20 + OFFSET(D19, 0, -1) -> 0 | E19: =INDEX($C$15:$K$15, 1, MAX(E5 - Scenarios!$B$26, MIN(E5, 3))) * Scenarios!$B$20 + OFFSET(E19, 0, -1) -> 90 | F19: =INDEX($C$15:$K$15, 1, MAX(F5 - Scenarios!$B$26, MIN(F5, 3))) * Scenarios!$B$20 + OFFSET(F19, 0, -1) -> 360 | G19: =INDEX($C$15:$K$15, 1, MAX(G5 - Scenarios!$B$26, MIN(G5, 3))) * Scenarios!$B$20 + OFFSET(G19, 0, -1) -> 1851 | H19: =INDEX($C$15:$K$15, 1, MAX(H5 - Scenarios!$B$26, MIN(H5, 3))) * Scenarios!$B$20 + OFFSET(H19, 0, -1) -> 5005 | I19: =INDEX($C$15:$K$15, 1, MAX(I5 - Scenarios!$B$26, MIN(I5, 3))) * Scenarios!$B$20 + OFFSET(I19, 0, -1) -> 12580 | L19: headsets
A21: 2. HARDWARE PRICING
A22: Hardware ASP | C22: 300 | D22: 300 | E22: 300 | F22: 300 | G22: 300 | H22: 300 | I22: 300 | L22: £/unit | M22: ch.9 §9.4: mid of £250–350 range; allow time-varying
A23: Returns allowance | B23: 0.02 | L23: % of hardware revenue | M23: ch.9 §Warranty and Returns: DOA + trial-period returns only; in-warranty repairs covered separately by warranty provision
A24: 3. GTM CHANNEL MIX, SUBSCRIPTION & MARKETING SPLIT
A26: Headsets per institutional buyer | B26: 3 | L26: headsets/buyer | M26: ch.10 §10.2: schools/clubs each cover multiple sports
A27: Subscription price per headset | B27: 600 | L27: £/headset/yr | M27: ch.10 §10.2: flat £600/yr; per-headset billing
A28: Institutional buyers (schools + clubs) | C28: 0 | D28: 0 | E28: 30 | F28: 90 | G28: 150 | H28: 400 | I28: 750 | L28: buyers | M28: ch.10 §10.2 (Phase 2 paid + Phase 3 institutional, scaling through Y7)
A29: DTC buyers (direct-to-consumer, no subscription) | C29: 0 | D29: 0 | E29: 0 | F29: 0 | G29: 1041 | H29: 1954 | I29: 5325 | L29: buyers | M29: ch.10 §10.3 (3% / 4% / 6% conversion ramp on effective exposure)
A30: Institutional channel marketing | C30: 5000 | D30: 10000 | E30: 25000 | F30: 50000 | G30: 50000 | H30: 75000 | I30: 100000 | L30: £/yr | M30: B2B sales floor: conferences, sales reps, materials
A31: DTC channel marketing | C31: 0 | D31: 0 | E31: 0 | F31: 0 | G31: 100000 | H31: 225000 | I31: 400000 | L31: £/yr | M31: Parent acquisition: digital, social, content marketing
A32: Subscription ARPU per headset | C32: =$B$27 * Scenarios!$B$28 -> 600 | D32: =$B$27 * Scenarios!$B$28 -> 600 | E32: =$B$27 * Scenarios!$B$28 -> 600 | F32: =$B$27 * Scenarios!$B$28 -> 600 | G32: =$B$27 * Scenarios!$B$28 -> 600 | H32: =$B$27 * Scenarios!$B$28 -> 600 | I32: =$B$27 * Scenarios!$B$28 -> 600 | L32: £/sub/yr | M32: = $B$27 × ARPU scenario multiplier
A33: Subscription attach (per institutional headset) | B33: 1 | L33: % of inst. headsets | M33: 100% by construction; DTC excluded in row 17 by using delayed_inst
A34: 4. OTHER REVENUE LINES (toggle on/off)
A35: Research licences (1 = on, 0 = off) | B35: 0
A36: Research licence sites per year | C36: 2 | D36: 5 | E36: 8 | F36: 10 | G36: 12 | H36: 14 | I36: 15 | L36: sites
A37: Research licence £ per site per year | B37: 3000 | L37: £/site/yr
A38: Accessories & consumables (1 = on, 0 = off) | B38: 0
A39: Accessories £/yr per active subscriber | B39: 20 | L39: £/sub/yr | M39: Wipes, replacement facial interfaces, straps
A40: Accessories gross margin % | B40: 0.6 | L40: % | M40: Markup on consumables; assumed similar to medical disposables
A41: Extended warranty (1 = on, 0 = off) | B41: 0
A42: Extended warranty attach % at point of sale | B42: 0.15 | L42: %
A43: Extended warranty £ per attached unit | B43: 45 | L43: £/unit
A44: Extended warranty gross margin % | B44: 0.45 | L44: % | M44: ch.9 §9.5: 40–50% range
A45: 5. COST OF GOODS SOLD
...

Sheet Unit economics
A1: Unit Economics — Per-customer profitability
A2: All values driven from the Assumptions tab. Y6–Y7 are the steady-state reference (P3 mature, post-breakeven).
A4: Year | C4: =Assumptions!C4 -> Y1 | D4: =Assumptions!D4 -> Y2 | E4: =Assumptions!E4 -> Y3 | F4: =Assumptions!F4 -> Y4 | G4: =Assumptions!G4 -> Y5 | H4: =Assumptions!H4 -> Y6 | I4: =Assumptions!I4 -> Y7
A5: Period number | C5: =Assumptions!C5 -> 1 | D5: =Assumptions!D5 -> 2 | E5: =Assumptions!E5 -> 3 | F5: =Assumptions!F5 -> 4 | G5: =Assumptions!G5 -> 5 | H5: =Assumptions!H5 -> 6 | I5: =Assumptions!I5 -> 7
A6: Phase | C6: =Assumptions!C7 -> 1 | D6: =Assumptions!D7 -> 1 | E6: =Assumptions!E7 -> 2 | F6: =Assumptions!F7 -> 2 | G6: =Assumptions!G7 -> 3 | H6: =Assumptions!H7 -> 3 | I6: =Assumptions!I7 -> 3
A8: 1. HARDWARE ECONOMICS (per unit)
A9: Hardware ASP | C9: =Assumptions!C22 -> 300 | D9: =Assumptions!D22 -> 300 | E9: =Assumptions!E22 -> 300 | F9: =Assumptions!F22 -> 300 | G9: =Assumptions!G22 -> 300 | H9: =Assumptions!H22 -> 300 | I9: =Assumptions!I22 -> 300 | L9: £/unit
A10: Effective unit cost | C10: =Assumptions!C49 -> 340 | D10: =Assumptions!D49 -> 340 | E10: =Assumptions!E49 -> 285 | F10: =Assumptions!F49 -> 285 | G10: =Assumptions!G49 -> 174 | H10: =Assumptions!H49 -> 174 | I10: =Assumptions!I49 -> 174 | L10: £/unit
A11: Hardware contribution per unit | C11: =C9 - C10 -> -40 | D11: =D9 - D10 -> -40 | E11: =E9 - E10 -> 15 | F11: =F9 - F10 -> 15 | G11: =G9 - G10 -> 126 | H11: =H9 - H10 -> 126 | I11: =I9 - I10 -> 126 | L11: £/unit
A12: Hardware gross margin % | C12: =IFERROR(C11/C9, 0) -> -0.13333333 | D12: =IFERROR(D11/D9, 0) -> -0.13333333 | E12: =IFERROR(E11/E9, 0) -> 0.05 | F12: =IFERROR(F11/F9, 0) -> 0.05 | G12: =IFERROR(G11/G9, 0) -> 0.42 | H12: =IFERROR(H11/H9, 0) -> 0.42 | I12: =IFERROR(I11/I9, 0) -> 0.42 | L12: %
A14: 2. SUBSCRIPTION ECONOMICS (per active customer per year)
A15: Blended ARPU | C15: =Assumptions!C32 -> 600 | D15: =Assumptions!D32 -> 600 | E15: =Assumptions!E32 -> 600 | F15: =Assumptions!F32 -> 600 | G15: =Assumptions!G32 -> 600 | H15: =Assumptions!H32 -> 600 | I15: =Assumptions!I32 -> 600 | L15: £/sub/yr
A16: Subscription COGS rate | C16: =Assumptions!$B$50 -> 0.15 | D16: =Assumptions!$B$50 -> 0.15 | E16: =Assumptions!$B$50 -> 0.15 | F16: =Assumptions!$B$50 -> 0.15 | G16: =Assumptions!$B$50 -> 0.15 | H16: =Assumptions!$B$50 -> 0.15 | I16: =Assumptions!$B$50 -> 0.15 | L16: %
A17: Subscription contribution | C17: =C15 * (1 - C16) -> 510 | D17: =D15 * (1 - D16) -> 510 | E17: =E15 * (1 - E16) -> 510 | F17: =F15 * (1 - F16) -> 510 | G17: =G15 * (1 - G16) -> 510 | H17: =H15 * (1 - H16) -> 510 | I17: =I15 * (1 - I16) -> 510 | L17: £/sub/yr
A18: Subscription gross margin % | C18: =IFERROR(C17/C15, 0) -> 0.85 | D18: =IFERROR(D17/D15, 0) -> 0.85 | E18: =IFERROR(E17/E15, 0) -> 0.85 | F18: =IFERROR(F17/F15, 0) -> 0.85 | G18: =IFERROR(G17/G15, 0) -> 0.85 | H18: =IFERROR(H17/H15, 0) -> 0.85 | I18: =IFERROR(I17/I15, 0) -> 0.85 | L18: %
A20: 3. ACCESSORIES & CONSUMABLES (per active customer per year)
A21: Accessories enabled (1 = on, 0 = off) | C21: =Assumptions!$B$38 -> 0 | D21: =Assumptions!$B$38 -> 0 | E21: =Assumptions!$B$38 -> 0 | F21: =Assumptions!$B$38 -> 0 | G21: =Assumptions!$B$38 -> 0 | H21: =Assumptions!$B$38 -> 0 | I21: =Assumptions!$B$38 -> 0
A22: Accessories revenue per active sub | C22: =C21 * Assumptions!$B$39 -> 0 | D22: =D21 * Assumptions!$B$39 -> 0 | E22: =E21 * Assumptions!$B$39 -> 0 | F22: =F21 * Assumptions!$B$39 -> 0 | G22: =G21 * Assumptions!$B$39 -> 0 | H22: =H21 * Assumptions!$B$39 -> 0 | I22: =I21 * Assumptions!$B$39 -> 0 | L22: £/sub/yr
A23: Accessories gross margin % | C23: =Assumptions!$B$40 -> 0.6 | D23: =Assumptions!$B$40 -> 0.6 | E23: =Assumptions!$B$40 -> 0.6 | F23: =Assumptions!$B$40 -> 0.6 | G23: =Assumptions!$B$40 -> 0.6 | H23: =Assumptions!$B$40 -> 0.6 | I23: =Assumptions!$B$40 -> 0.6 | L23: %
A24: Accessories contribution per active sub | C24: =C22 * C23 -> 0 | D24: =D22 * D23 -> 0 | E24: =E22 * E23 -> 0 | F24: =F22 * F23 -> 0 | G24: =G22 * G23 -> 0 | H24: =H22 * H23 -> 0 | I24: =I22 * I23 -> 0 | L24: £/sub/yr
A26: 4. EXTENDED WARRANTY (one-off, per new customer at sale)
A27: Warranty enabled (1 = on, 0 = off) | C27: =Assumptions!$B$41 -> 0 | D27: =Assumptions!$B$41 -> 0 | E27: =Assumptions!$B$41 -> 0 | F27: =Assumptions!$B$41 -> 0 | G27: =Assumptions!$B$41 -> 0 | H27: =Assumptions!$B$41 -> 0 | I27: =Assumptions!$B$41 -> 0
A28: Attach % at sale | C28: =Assumptions!$B$42 -> 0.15 | D28: =Assumptions!$B$42 -> 0.15 | E28: =Assumptions!$B$42 -> 0.15 | F28: =Assumptions!$B$42 -> 0.15 | G28: =Assumptions!$B$42 -> 0.15 | H28: =Assumptions!$B$42 -> 0.15 | I28: =Assumptions!$B$42 -> 0.15 | L28: %
A29: Warranty £ per attached unit | C29: =Assumptions!$B$43 -> 45 | D29: =Assumptions!$B$43 -> 45 | E29: =Assumptions!$B$43 -> 45 | F29: =Assumptions!$B$43 -> 45 | G29: =Assumptions!$B$43 -> 45 | H29: =Assumptions!$B$43 -> 45 | I29: =Assumptions!$B$43 -> 45 | L29: £
A30: Warranty gross margin % | C30: =Assumptions!$B$44 -> 0.45 | D30: =Assumptions!$B$44 -> 0.45 | E30: =Assumptions!$B$44 -> 0.45 | F30: =Assumptions!$B$44 -> 0.45 | G30: =Assumptions!$B$44 -> 0.45 | H30: =Assumptions!$B$44 -> 0.45 | I30: =Assumptions!$B$44 -> 0.45 | L30: %
A31: Warranty contribution per new unit | C31: =C27 * C28 * C29 * C30 -> 0 | D31: =D27 * D28 * D29 * D30 -> 0 | E31: =E27 * E28 * E29 * E30 -> 0 | F31: =F27 * F28 * F29 * F30 -> 0 | G31: =G27 * G28 * G29 * G30 -> 0 | H31: =H27 * H28 * H29 * H30 -> 0 | I31: =I27 * I28 * I29 * I30 -> 0 | L31: £/unit
A33: 5. TOTAL ANNUAL ECONOMICS (per active customer)
A34: Total annual revenue per active customer | C34: =C15 + C22 -> 600 | D34: =D15 + D22 -> 600 | E34: =E15 + E22 -> 600 | F34: =F15 + F22 -> 600 | G34: =G15 + G22 -> 600 | H34: =H15 + H22 -> 600 | I34: =I15 + I22 -> 600 | L34: £/sub/yr | M34: = ARPU + accessories revenue
A35: Total annual contribution per active customer | C35: =C17 + C24 -> 510 | D35: =D17 + D24 -> 510 | E35: =E17 + E24 -> 510 | F35: =F17 + F24 -> 510 | G35: =G17 + G24 -> 510 | H35: =H17 + H24 -> 510 | I35: =I17 + I24 -> 510 | L35: £/sub/yr | M35: = sub contribution + accessories contribution
A37: 6. CUSTOMER LIFETIME VALUE (LTV)
A38: Annual subscription churn | C38: =Assumptions!$B$16 -> 0.1 | D38: =Assumptions!$B$16 -> 0.1 | E38: =Assumptions!$B$16 -> 0.1 | F38: =Assumptions!$B$16 -> 0.1 | G38: =Assumptions!$B$16 -> 0.1 | H38: =Assumptions!$B$16 -> 0.1 | I38: =Assumptions!$B$16 -> 0.1 | L38: %
A39: Implied avg customer lifetime | C39: =IFERROR(1/C38, 0) -> 10 | D39: =IFERROR(1/D38, 0) -> 10 | E39: =IFERROR(1/E38, 0) -> 10 | F39: =IFERROR(1/F38, 0) -> 10 | G39: =IFERROR(1/G38, 0) -> 10 | H39: =IFERROR(1/H38, 0) -> 10 | I39: =IFERROR(1/I38, 0) -> 10 | L39: years | M39: = 1 / churn (perpetuity equivalent)
A40: 3-year LTV factor (sub side) | C40: =1 + (1-C38) + (1-C38)^2 -> 2.71 | D40: =1 + (1-D38) + (1-D38)^2 -> 2.71 | E40: =1 + (1-E38) + (1-E38)^2 -> 2.71 | F40: =1 + (1-F38) + (1-F38)^2 -> 2.71 | G40: =1 + (1-G38) + (1-G38)^2 -> 2.71 | H40: =1 + (1-H38) + (1-H38)^2 -> 2.71 | I40: =1 + (1-I38) + (1-I38)^2 -> 2.71 | L40: multiplier | M40: = 1 + (1−c) + (1−c)²
A41: 3-year sub + accessories LTV | C41: =C35 * C40 -> 1382.1 | D41: =D35 * D40 -> 1382.1 | E41: =E35 * E40 -> 1382.1 | F41: =F35 * F40 -> 1382.1 | G41: =G35 * G40 -> 1382.1 | H41: =H35 * H40 -> 1382.1 | I41: =I35 * I40 -> 1382.1 | L41: £/customer
A42: 3-year total LTV per customer | C42: =C11 + C31 + C41 -> 1342.1 | D42: =D11 + D31 + D41 -> 1342.1 | E42: =E11 + E31 + E41 -> 1397.1 | F42: =F11 + F31 + F41 -> 1397.1 | G42: =G11 + G31 + G41 -> 1508.1 | H42: =H11 + H31 + H41 -> 1508.1 | I42: =I11 + I31 + I41 -> 1508.1 | L42: £/customer | M42: = HW contribution + warranty contribution + 3-yr sub+acc LTV
A43: Steady-state sub + accessories LTV | C43: =IFERROR(C35/C38, 0) -> 5100 | D43: =IFERROR(D35/D38, 0) -> 5100 | E43: =IFERROR(E35/E38, 0) -> 5100 | F43: =IFERROR(F35/F38, 0) -> 5100 | G43: =IFERROR(G35/G38, 0) -> 5100 | H43: =IFERROR(H35/H38, 0) -> 5100 | I43: =IFERROR(I35/I38, 0) -> 5100 | L43: £/customer | M43: = annual contribution / churn (perpetuity)
A44: Steady-state total LTV per customer | C44: =C11 + C31 + C43 -> 5060 | D44: =D11 + D31 + D43 -> 5060 | E44: =E11 + E31 + E43 -> 5115 | F44: =F11 + F31 + F43 -> 5115 | G44: =G11 + G31 + G43 -> 5226 | H44: =H11 + H31 + H43 -> 5226 | I44: =I11 + I31 + I43 -> 5226 | L44: £/customer
A46: 7. CUSTOMER ACQUISITION COST (by channel)
A47: Institutional channel marketing | C47: =Assumptions!C30 -> 5000 | D47: =Assumptions!D30 -> 10000 | E47: =Assumptions!E30 -> 25000 | F47: =Assumptions!F30 -> 50000 | G47: =Assumptions!G30 -> 50000 | H47: =Assumptions!H30 -> 75000 | I47: =Assumptions!I30 -> 100000 | L47: £/yr
A48: Sales commission (institutional only) | C48: =Assumptions!C68 -> 0 | D48: =Assumptions!D68 -> 0 | E48: =Assumptions!E68 -> 8100 | F48: =Assumptions!F68 -> 24300 | G48: =Assumptions!G68 -> 40500 | H48: =Assumptions!H68 -> 108000 | I48: =Assumptions!I68 -> 202500 | L48: £/yr
...

Sheet P&L
A1: Profit & Loss — 7-year projection
A2: Driven from the Assumptions tab. Read the EBITDA line for the headline shape; read R&D credit + corp tax for the cash impact of loss-making years.
A4: Year | C4: =Assumptions!C4 -> Y1 | D4: =Assumptions!D4 -> Y2 | E4: =Assumptions!E4 -> Y3 | F4: =Assumptions!F4 -> Y4 | G4: =Assumptions!G4 -> Y5 | H4: =Assumptions!H4 -> Y6 | I4: =Assumptions!I4 -> Y7
A5: Period number | C5: =Assumptions!C5 -> 1 | D5: =Assumptions!D5 -> 2 | E5: =Assumptions!E5 -> 3 | F5: =Assumptions!F5 -> 4 | G5: =Assumptions!G5 -> 5 | H5: =Assumptions!H5 -> 6 | I5: =Assumptions!I5 -> 7
A6: Phase | C6: =Assumptions!C7 -> 1 | D6: =Assumptions!D7 -> 1 | E6: =Assumptions!E7 -> 2 | F6: =Assumptions!F7 -> 2 | G6: =Assumptions!G7 -> 3 | H6: =Assumptions!H7 -> 3 | I6: =Assumptions!I7 -> 3
A8: 1. REVENUE
A9: Hardware revenue | C9: =INDEX(Assumptions!$C$15:$K$15, 1, MAX(C5 - Scenarios!$B$26, MIN(C5, 3))) * Scenarios!$B$20 * Assumptions!C22 * Scenarios!$B$27 * (1 - Assumptions!$B$23) -> 0 | D9: =INDEX(Assumptions!$C$15:$K$15, 1, MAX(D5 - Scenarios!$B$26, MIN(D5, 3))) * Scenarios!$B$20 * Assumptions!D22 * Scenarios!$B$27 * (1 - Assumptions!$B$23) -> 0 | E9: =INDEX(Assumptions!$C$15:$K$15, 1, MAX(E5 - Scenarios!$B$26, MIN(E5, 3))) * Scenarios!$B$20 * Assumptions!E22 * Scenarios!$B$27 * (1 - Assumptions!$B$23) -> 26460 | F9: =INDEX(Assumptions!$C$15:$K$15, 1, MAX(F5 - Scenarios!$B$26, MIN(F5, 3))) * Scenarios!$B$20 * Assumptions!F22 * Scenarios!$B$27 * (1 - Assumptions!$B$23) -> 79380 | G9: =INDEX(Assumptions!$C$15:$K$15, 1, MAX(G5 - Scenarios!$B$26, MIN(G5, 3))) * Scenarios!$B$20 * Assumptions!G22 * Scenarios!$B$27 * (1 - Assumptions!$B$23) -> 438354 | H9: =INDEX(Assumptions!$C$15:$K$15, 1, MAX(H5 - Scenarios!$B$26, MIN(H5, 3))) * Scenarios!$B$20 * Assumptions!H22 * Scenarios!$B$27 * (1 - Assumptions!$B$23) -> 927276 | I9: =INDEX(Assumptions!$C$15:$K$15, 1, MAX(I5 - Scenarios!$B$26, MIN(I5, 3))) * Scenarios!$B$20 * Assumptions!I22 * Scenarios!$B$27 * (1 - Assumptions!$B$23) -> 2227050 | L9: £ | M9: delay-shifted new units × adoption × ASP × ASP scenario × (1 − returns allowance)
A10: Subscription revenue | C10: =Assumptions!C18 * Assumptions!C32 -> 0 | D10: =Assumptions!D18 * Assumptions!D32 -> 0 | E10: =Assumptions!E18 * Assumptions!E32 -> 27000 | F10: =Assumptions!F18 * Assumptions!F32 -> 132300 | G10: =Assumptions!G18 * Assumptions!G32 -> 335070 | H10: =Assumptions!H18 * Assumptions!H32 -> 796563 | I10: =Assumptions!I18 * Assumptions!I32 -> 1751906.7 | L10: £ | M10: average subscribers × blended ARPU
A11: Research licence revenue | C11: =Assumptions!$B$35 * Assumptions!C36 * Assumptions!$B$37 -> 0 | D11: =Assumptions!$B$35 * Assumptions!D36 * Assumptions!$B$37 -> 0 | E11: =Assumptions!$B$35 * Assumptions!E36 * Assumptions!$B$37 -> 0 | F11: =Assumptions!$B$35 * Assumptions!F36 * Assumptions!$B$37 -> 0 | G11: =Assumptions!$B$35 * Assumptions!G36 * Assumptions!$B$37 -> 0 | H11: =Assumptions!$B$35 * Assumptions!H36 * Assumptions!$B$37 -> 0 | I11: =Assumptions!$B$35 * Assumptions!I36 * Assumptions!$B$37 -> 0 | L11: £ | M11: toggle × sites × £/site
A12: Accessories & consumables revenue | C12: =Assumptions!$B$38 * Assumptions!C18 * Assumptions!$B$39 -> 0 | D12: =Assumptions!$B$38 * Assumptions!D18 * Assumptions!$B$39 -> 0 | E12: =Assumptions!$B$38 * Assumptions!E18 * Assumptions!$B$39 -> 0 | F12: =Assumptions!$B$38 * Assumptions!F18 * Assumptions!$B$39 -> 0 | G12: =Assumptions!$B$38 * Assumptions!G18 * Assumptions!$B$39 -> 0 | H12: =Assumptions!$B$38 * Assumptions!H18 * Assumptions!$B$39 -> 0 | I12: =Assumptions!$B$38 * Assumptions!I18 * Assumptions!$B$39 -> 0 | L12: £ | M12: toggle × avg subs × £/sub/yr
A13: Extended warranty revenue | C13: =Assumptions!$B$41 * INDEX(Assumptions!$C$15:$K$15, 1, MAX(C5 - Scenarios!$B$26, MIN(C5, 3))) * Scenarios!$B$20 * Assumptions!$B$42 * Assumptions!$B$43 -> 0 | D13: =Assumptions!$B$41 * INDEX(Assumptions!$C$15:$K$15, 1, MAX(D5 - Scenarios!$B$26, MIN(D5, 3))) * Scenarios!$B$20 * Assumptions!$B$42 * Assumptions!$B$43 -> 0 | E13: =Assumptions!$B$41 * INDEX(Assumptions!$C$15:$K$15, 1, MAX(E5 - Scenarios!$B$26, MIN(E5, 3))) * Scenarios!$B$20 * Assumptions!$B$42 * Assumptions!$B$43 -> 0 | F13: =Assumptions!$B$41 * INDEX(Assumptions!$C$15:$K$15, 1, MAX(F5 - Scenarios!$B$26, MIN(F5, 3))) * Scenarios!$B$20 * Assumptions!$B$42 * Assumptions!$B$43 -> 0 | G13: =Assumptions!$B$41 * INDEX(Assumptions!$C$15:$K$15, 1, MAX(G5 - Scenarios!$B$26, MIN(G5, 3))) * Scenarios!$B$20 * Assumptions!$B$42 * Assumptions!$B$43 -> 0 | H13: =Assumptions!$B$41 * INDEX(Assumptions!$C$15:$K$15, 1, MAX(H5 - Scenarios!$B$26, MIN(H5, 3))) * Scenarios!$B$20 * Assumptions!$B$42 * Assumptions!$B$43 -> 0 | I13: =Assumptions!$B$41 * INDEX(Assumptions!$C$15:$K$15, 1, MAX(I5 - Scenarios!$B$26, MIN(I5, 3))) * Scenarios!$B$20 * Assumptions!$B$42 * Assumptions!$B$43 -> 0 | L13: £ | M13: toggle × delay-shifted new units × adoption × attach × £/unit
A14: TOTAL REVENUE | C14: =SUM(C9:C13) -> 0 | D14: =SUM(D9:D13) -> 0 | E14: =SUM(E9:E13) -> 53460 | F14: =SUM(F9:F13) -> 211680 | G14: =SUM(G9:G13) -> 773424 | H14: =SUM(H9:H13) -> 1723839 | I14: =SUM(I9:I13) -> 3978956.7 | L14: £
A16: 2. COST OF GOODS SOLD
A17: Hardware COGS | C17: =INDEX(Assumptions!$C$15:$K$15, 1, MAX(C5 - Scenarios!$B$26, MIN(C5, 3))) * Scenarios!$B$20 * Assumptions!C49 -> 0 | D17: =INDEX(Assumptions!$C$15:$K$15, 1, MAX(D5 - Scenarios!$B$26, MIN(D5, 3))) * Scenarios!$B$20 * Assumptions!D49 -> 0 | E17: =INDEX(Assumptions!$C$15:$K$15, 1, MAX(E5 - Scenarios!$B$26, MIN(E5, 3))) * Scenarios!$B$20 * Assumptions!E49 -> 25650 | F17: =INDEX(Assumptions!$C$15:$K$15, 1, MAX(F5 - Scenarios!$B$26, MIN(F5, 3))) * Scenarios!$B$20 * Assumptions!F49 -> 76950 | G17: =INDEX(Assumptions!$C$15:$K$15, 1, MAX(G5 - Scenarios!$B$26, MIN(G5, 3))) * Scenarios!$B$20 * Assumptions!G49 -> 259434 | H17: =INDEX(Assumptions!$C$15:$K$15, 1, MAX(H5 - Scenarios!$B$26, MIN(H5, 3))) * Scenarios!$B$20 * Assumptions!H49 -> 548796 | I17: =INDEX(Assumptions!$C$15:$K$15, 1, MAX(I5 - Scenarios!$B$26, MIN(I5, 3))) * Scenarios!$B$20 * Assumptions!I49 -> 1318050 | L17: £ | M17: delay-shifted new units × adoption × effective unit cost (BOM applied in row 49)
A18: Subscription COGS | C18: =C10 * Assumptions!$B$50 -> 0 | D18: =D10 * Assumptions!$B$50 -> 0 | E18: =E10 * Assumptions!$B$50 -> 4050 | F18: =F10 * Assumptions!$B$50 -> 19845 | G18: =G10 * Assumptions!$B$50 -> 50260.5 | H18: =H10 * Assumptions!$B$50 -> 119484.45 | I18: =I10 * Assumptions!$B$50 -> 262786.01 | L18: £ | M18: hosting / support tooling — sub rev × COGS rate
A19: Accessories COGS | C19: =C12 * (1 - Assumptions!$B$40) -> 0 | D19: =D12 * (1 - Assumptions!$B$40) -> 0 | E19: =E12 * (1 - Assumptions!$B$40) -> 0 | F19: =F12 * (1 - Assumptions!$B$40) -> 0 | G19: =G12 * (1 - Assumptions!$B$40) -> 0 | H19: =H12 * (1 - Assumptions!$B$40) -> 0 | I19: =I12 * (1 - Assumptions!$B$40) -> 0 | L19: £
A20: Extended warranty COGS | C20: =C13 * (1 - Assumptions!$B$44) -> 0 | D20: =D13 * (1 - Assumptions!$B$44) -> 0 | E20: =E13 * (1 - Assumptions!$B$44) -> 0 | F20: =F13 * (1 - Assumptions!$B$44) -> 0 | G20: =G13 * (1 - Assumptions!$B$44) -> 0 | H20: =H13 * (1 - Assumptions!$B$44) -> 0 | I20: =I13 * (1 - Assumptions!$B$44) -> 0 | L20: £
A21: TOTAL COGS | C21: =SUM(C17:C20) -> 0 | D21: =SUM(D17:D20) -> 0 | E21: =SUM(E17:E20) -> 29700 | F21: =SUM(F17:F20) -> 96795 | G21: =SUM(G17:G20) -> 309694.5 | H21: =SUM(H17:H20) -> 668280.45 | I21: =SUM(I17:I20) -> 1580836 | L21: £
A23: GROSS PROFIT | C23: =C14 - C21 -> 0 | D23: =D14 - D21 -> 0 | E23: =E14 - E21 -> 23760 | F23: =F14 - F21 -> 114885 | G23: =G14 - G21 -> 463729.5 | H23: =H14 - H21 -> 1055558.6 | I23: =I14 - I21 -> 2398120.7 | L23: £
A24: Gross margin % | C24: =IFERROR(C23/C14, 0) -> 0 | D24: =IFERROR(D23/D14, 0) -> 0 | E24: =IFERROR(E23/E14, 0) -> 0.44444444 | F24: =IFERROR(F23/F14, 0) -> 0.54272959 | G24: =IFERROR(G23/G14, 0) -> 0.59957992 | H24: =IFERROR(H23/H14, 0) -> 0.61233012 | I24: =IFERROR(I23/I14, 0) -> 0.60270088 | L24: %
A26: 3. OPERATING EXPENSES — R&D
A27: Engineering payroll (allocated) | C27: =IFERROR(Assumptions!$B$55 * Assumptions!C55 / Assumptions!C63, 0) * Assumptions!C66 -> 168952.33 | D27: =IFERROR(Assumptions!$B$55 * Assumptions!D55 / Assumptions!D63, 0) * Assumptions!D66 -> 174329.44 | E27: =IFERROR(Assumptions!$B$55 * Assumptions!E55 / Assumptions!E63, 0) * Assumptions!E66 -> 261800 | F27: =IFERROR(Assumptions!$B$55 * Assumptions!F55 / Assumptions!F63, 0) * Assumptions!F66 -> 327250 | G27: =IFERROR(Assumptions!$B$55 * Assumptions!G55 / Assumptions!G63, 0) * Assumptions!G66 -> 392700 | H27: =IFERROR(Assumptions!$B$55 * Assumptions!H55 / Assumptions!H63, 0) * Assumptions!H66 -> 458150 | I27: =IFERROR(Assumptions!$B$55 * Assumptions!I55 / Assumptions!I63, 0) * Assumptions!I66 -> 523600 | L27: £ | M27: (Eng base ÷ total base) × loaded payroll
A28: R&D non-payroll | C28: =Assumptions!C72 -> 15000 | D28: =Assumptions!D72 -> 20000 | E28: =Assumptions!E72 -> 25000 | F28: =Assumptions!F72 -> 30000 | G28: =Assumptions!G72 -> 30000 | H28: =Assumptions!H72 -> 30000 | I28: =Assumptions!I72 -> 30000 | L28: £
A29: TOTAL R&D | C29: =C27 + C28 -> 183952.33 | D29: =D27 + D28 -> 194329.44 | E29: =E27 + E28 -> 286800 | F29: =F27 + F28 -> 357250 | G29: =G27 + G28 -> 422700 | H29: =H27 + H28 -> 488150 | I29: =I27 + I28 -> 553600 | L29: £
A31: 4. OPERATING EXPENSES — REGULATORY & CLINICAL
A32: Regulatory & quality payroll (allocated) | C32: =IFERROR(Assumptions!$B$56 * Assumptions!C56 / Assumptions!C63, 0) * Assumptions!C66 -> 0 | D32: =IFERROR(Assumptions!$B$56 * Assumptions!D56 / Assumptions!D63, 0) * Assumptions!D66 -> 34337.617 | E32: =IFERROR(Assumptions!$B$56 * Assumptions!E56 / Assumptions!E63, 0) * Assumptions!E66 -> 77350 | F32: =IFERROR(Assumptions!$B$56 * Assumptions!F56 / Assumptions!F63, 0) * Assumptions!F66 -> 116025 | G32: =IFERROR(Assumptions!$B$56 * Assumptions!G56 / Assumptions!G63, 0) * Assumptions!G66 -> 154700 | H32: =IFERROR(Assumptions!$B$56 * Assumptions!H56 / Assumptions!H63, 0) * Assumptions!H66 -> 154700 | I32: =IFERROR(Assumptions!$B$56 * Assumptions!I56 / Assumptions!I63, 0) * Assumptions!I66 -> 154700 | L32: £
A33: Clinical research payroll (allocated) | C33: =IFERROR(Assumptions!$B$57 * Assumptions!C57 / Assumptions!C63, 0) * Assumptions!C66 -> 0 | D33: =IFERROR(Assumptions!$B$57 * Assumptions!D57 / Assumptions!D63, 0) * Assumptions!D66 -> 21130.841 | E33: =IFERROR(Assumptions!$B$57 * Assumptions!E57 / Assumptions!E63, 0) * Assumptions!E66 -> 47600 | F33: =IFERROR(Assumptions!$B$57 * Assumptions!F57 / Assumptions!F63, 0) * Assumptions!F66 -> 47600 | G33: =IFERROR(Assumptions!$B$57 * Assumptions!G57 / Assumptions!G63, 0) * Assumptions!G66 -> 47600 | H33: =IFERROR(Assumptions!$B$57 * Assumptions!H57 / Assumptions!H63, 0) * Assumptions!H66 -> 47600 | I33: =IFERROR(Assumptions!$B$57 * Assumptions!I57 / Assumptions!I63, 0) * Assumptions!I66 -> 47600 | L33: £
A34: One-off regulatory & clinical | C34: =Assumptions!C86 * Scenarios!$B$25 -> 0 | D34: =Assumptions!D86 * Scenarios!$B$25 -> 130000 | E34: =Assumptions!E86 * Scenarios!$B$25 -> 140000 | F34: =Assumptions!F86 * Scenarios!$B$25 -> 0 | G34: =Assumptions!G86 * Scenarios!$B$25 -> 0 | H34: =Assumptions!H86 * Scenarios!$B$25 -> 0 | I34: =Assumptions!I86 * Scenarios!$B$25 -> 0 | L34: £ | M34: QMS, NB fees, biocompat, EMC, clinical investigation × reg scenario
A35: Ongoing PMS & NB surveillance | C35: =Assumptions!C87 * Scenarios!$B$25 -> 0 | D35: =Assumptions!D87 * Scenarios!$B$25 -> 0 | E35: =Assumptions!E87 * Scenarios!$B$25 -> 0 | F35: =Assumptions!F87 * Scenarios!$B$25 -> 55000 | G35: =Assumptions!G87 * Scenarios!$B$25 -> 55000 | H35: =Assumptions!H87 * Scenarios!$B$25 -> 60000 | I35: =Assumptions!I87 * Scenarios!$B$25 -> 65000 | L35: £ | M35: Post-market obligations × reg scenario
A36: TOTAL REGULATORY & CLINICAL | C36: =SUM(C32:C35) -> 0 | D36: =SUM(D32:D35) -> 185468.46 | E36: =SUM(E32:E35) -> 264950 | F36: =SUM(F32:F35) -> 218625 | G36: =SUM(G32:G35) -> 257300 | H36: =SUM(H32:H35) -> 262300 | I36: =SUM(I32:I35) -> 267300 | L36: £
A38: 5. OPERATING EXPENSES — SALES & MARKETING
A39: Sales / BD payroll (allocated) | C39: =IFERROR(Assumptions!$B$58 * Assumptions!C58 / Assumptions!C63, 0) * Assumptions!C66 -> 0 | D39: =IFERROR(Assumptions!$B$58 * Assumptions!D58 / Assumptions!D63, 0) * Assumptions!D66 -> 0 | E39: =IFERROR(Assumptions!$B$58 * Assumptions!E58 / Assumptions!E63, 0) * Assumptions!E66 -> 57120 | F39: =IFERROR(Assumptions!$B$58 * Assumptions!F58 / Assumptions!F63, 0) * Assumptions!F66 -> 114240 | G39: =IFERROR(Assumptions!$B$58 * Assumptions!G58 / Assumptions!G63, 0) * Assumptions!G66 -> 171360 | H39: =IFERROR(Assumptions!$B$58 * Assumptions!H58 / Assumptions!H63, 0) * Assumptions!H66 -> 171360 | I39: =IFERROR(Assumptions!$B$58 * Assumptions!I58 / Assumptions!I63, 0) * Assumptions!I66 -> 171360 | L39: £
A40: Customer support payroll (allocated) | C40: =IFERROR(Assumptions!$B$60 * Assumptions!C60 / Assumptions!C63, 0) * Assumptions!C66 -> 0 | D40: =IFERROR(Assumptions!$B$60 * Assumptions!D60 / Assumptions!D63, 0) * Assumptions!D66 -> 0 | E40: =IFERROR(Assumptions!$B$60 * Assumptions!E60 / Assumptions!E63, 0) * Assumptions!E66 -> 0 | F40: =IFERROR(Assumptions!$B$60 * Assumptions!F60 / Assumptions!F63, 0) * Assumptions!F66 -> 19040 | G40: =IFERROR(Assumptions!$B$60 * Assumptions!G60 / Assumptions!G63, 0) * Assumptions!G66 -> 38080 | H40: =IFERROR(Assumptions!$B$60 * Assumptions!H60 / Assumptions!H63, 0) * Assumptions!H66 -> 57120 | I40: =IFERROR(Assumptions!$B$60 * Assumptions!I60 / Assumptions!I63, 0) * Assumptions!I66 -> 76160 | L40: £
A41: Sales commission | C41: =Assumptions!C68 -> 0 | D41: =Assumptions!D68 -> 0 | E41: =Assumptions!E68 -> 8100 | F41: =Assumptions!F68 -> 24300 | G41: =Assumptions!G68 -> 40500 | H41: =Assumptions!H68 -> 108000 | I41: =Assumptions!I68 -> 202500 | L41: £
A42: Marketing | C42: =Assumptions!C73 * Scenarios!$B$24 -> 5000 | D42: =Assumptions!D73 * Scenarios!$B$24 -> 10000 | E42: =Assumptions!E73 * Scenarios!$B$24 -> 25000 | F42: =Assumptions!F73 * Scenarios!$B$24 -> 50000 | G42: =Assumptions!G73 * Scenarios!$B$24 -> 150000 | H42: =Assumptions!H73 * Scenarios!$B$24 -> 300000 | I42: =Assumptions!I73 * Scenarios!$B$24 -> 500000 | L42: £ | M42: Marketing spend × marketing scenario
A43: TOTAL SALES & MARKETING | C43: =SUM(C39:C42) -> 5000 | D43: =SUM(D39:D42) -> 10000 | E43: =SUM(E39:E42) -> 90220 | F43: =SUM(F39:F42) -> 207580 | G43: =SUM(G39:G42) -> 399940 | H43: =SUM(H39:H42) -> 636480 | I43: =SUM(I39:I42) -> 950020 | L43: £
A45: 6. OPERATING EXPENSES — GENERAL & ADMINISTRATIVE
A46: CEO / commercial payroll (allocated) | C46: =IFERROR(Assumptions!$B$54 * Assumptions!C54 / Assumptions!C63, 0) * Assumptions!C66 -> 51197.674 | D46: =IFERROR(Assumptions!$B$54 * Assumptions!D54 / Assumptions!D63, 0) * Assumptions!D66 -> 52827.103 | E46: =IFERROR(Assumptions!$B$54 * Assumptions!E54 / Assumptions!E63, 0) * Assumptions!E66 -> 59500 | F46: =IFERROR(Assumptions!$B$54 * Assumptions!F54 / Assumptions!F63, 0) * Assumptions!F66 -> 59500 | G46: =IFERROR(Assumptions!$B$54 * Assumptions!G54 / Assumptions!G63, 0) * Assumptions!G66 -> 59500 | H46: =IFERROR(Assumptions!$B$54 * Assumptions!H54 / Assumptions!H63, 0) * Assumptions!H66 -> 59500 | I46: =IFERROR(Assumptions!$B$54 * Assumptions!I54 / Assumptions!I63, 0) * Assumptions!I66 -> 59500 | L46: £
A47: Operations / supply chain payroll (allocated) | C47: =IFERROR(Assumptions!$B$59 * Assumptions!C59 / Assumptions!C63, 0) * Assumptions!C66 -> 0 | D47: =IFERROR(Assumptions!$B$59 * Assumptions!D59 / Assumptions!D63, 0) * Assumptions!D66 -> 0 | E47: =IFERROR(Assumptions!$B$59 * Assumptions!E59 / Assumptions!E63, 0) * Assumptions!E66 -> 0 | F47: =IFERROR(Assumptions!$B$59 * Assumptions!F59 / Assumptions!F63, 0) * Assumptions!F66 -> 53550 | G47: =IFERROR(Assumptions!$B$59 * Assumptions!G59 / Assumptions!G63, 0) * Assumptions!G66 -> 53550 | H47: =IFERROR(Assumptions!$B$59 * Assumptions!H59 / Assumptions!H63, 0) * Assumptions!H66 -> 53550 | I47: =IFERROR(Assumptions!$B$59 * Assumptions!I59 / Assumptions!I63, 0) * Assumptions!I66 -> 53550 | L47: £
A48: Spare role payroll (allocated) | C48: =IFERROR(Assumptions!$B$61 * Assumptions!C61 / Assumptions!C63, 0) * Assumptions!C66 -> 0 | D48: =IFERROR(Assumptions!$B$61 * Assumptions!D61 / Assumptions!D63, 0) * Assumptions!D66 -> 0 | E48: =IFERROR(Assumptions!$B$61 * Assumptions!E61 / Assumptions!E63, 0) * Assumptions!E66 -> 0 | F48: =IFERROR(Assumptions!$B$61 * Assumptions!F61 / Assumptions!F63, 0) * Assumptions!F66 -> 0 | G48: =IFERROR(Assumptions!$B$61 * Assumptions!G61 / Assumptions!G63, 0) * Assumptions!G66 -> 0 | H48: =IFERROR(Assumptions!$B$61 * Assumptions!H61 / Assumptions!H63, 0) * Assumptions!H66 -> 0 | I48: =IFERROR(Assumptions!$B$61 * Assumptions!I61 / Assumptions!I63, 0) * Assumptions!I66 -> 0 | L48: £
...

Sheet Cash flow
A1: Cash Flow — 7-year projection (indirect method)
A2: Builds operating cash from EBIT, layers in working capital and capex, then adds equity injections to derive closing cash. The minimum closing-cash point is the binding funding requirement.
A4: Year | C4: =Assumptions!C4 -> Y1 | D4: =Assumptions!D4 -> Y2 | E4: =Assumptions!E4 -> Y3 | F4: =Assumptions!F4 -> Y4 | G4: =Assumptions!G4 -> Y5 | H4: =Assumptions!H4 -> Y6 | I4: =Assumptions!I4 -> Y7
A5: Period number | C5: =Assumptions!C5 -> 1 | D5: =Assumptions!D5 -> 2 | E5: =Assumptions!E5 -> 3 | F5: =Assumptions!F5 -> 4 | G5: =Assumptions!G5 -> 5 | H5: =Assumptions!H5 -> 6 | I5: =Assumptions!I5 -> 7
A6: Phase | C6: =Assumptions!C7 -> 1 | D6: =Assumptions!D7 -> 1 | E6: =Assumptions!E7 -> 2 | F6: =Assumptions!F7 -> 2 | G6: =Assumptions!G7 -> 3 | H6: =Assumptions!H7 -> 3 | I6: =Assumptions!I7 -> 3
A8: 1. OPERATING CASH FLOW
A9: EBIT (operating profit / loss) | C9: ='P&L'!C63 -> -271450 | D9: ='P&L'!D63 -> -514125 | E9: ='P&L'!E63 -> -802210 | F9: ='P&L'!F63 -> -969120 | G9: ='P&L'!G63 -> -985760.5 | H9: ='P&L'!H63 -> -765021.45 | I9: ='P&L'!I63 -> 130607.84 | L9: £
A10: + Depreciation & amortisation (non-cash) | C10: ='P&L'!C61 -> 1300 | D10: ='P&L'!D61 -> 2500 | E10: ='P&L'!E61 -> 5500 | F10: ='P&L'!F61 -> 9500 | G10: ='P&L'!G61 -> 15500 | H10: ='P&L'!H61 -> 16600 | I10: ='P&L'!I61 -> 18542.857 | L10: £
A11: = EBITDA equivalent | C11: =C9 + C10 -> -270150 | D11: =D9 + D10 -> -511625 | E11: =E9 + E10 -> -796710 | F11: =F9 + F10 -> -959620 | G11: =G9 + G10 -> -970260.5 | H11: =H9 + H10 -> -748421.45 | I11: =I9 + I10 -> 149150.7 | L11: £
A12: − Tax paid / + R&D credit received | C12: =-'P&L'!C72 -> 21645.08 | D12: =-'P&L'!D72 -> 38998.985 | E12: =-'P&L'!E72 -> 55297.8 | F12: =-'P&L'!F72 -> 53389.44 | G12: =-'P&L'!G72 -> 63571.08 | H12: =-'P&L'!H72 -> 70875.3 | I12: =-'P&L'!I72 -> 78179.52 | L12: £ | M12: Assumes credit received in year incurred (1-yr lag in reality)
A13: = Operating cash before working capital | C13: =C11 + C12 -> -248504.92 | D13: =D11 + D12 -> -472626.01 | E13: =E11 + E12 -> -741412.2 | F13: =F11 + F12 -> -906230.56 | G13: =G11 + G12 -> -906689.42 | H13: =H11 + H12 -> -677546.15 | I13: =I11 + I12 -> 227330.21 | L13: £
A15: 2. WORKING CAPITAL CHANGES (positive = cash inflow)
A16: Inventory (end of year) | C16: =Assumptions!$B$110 * 'P&L'!C21 / 365 -> 0 | D16: =Assumptions!$B$110 * 'P&L'!D21 / 365 -> 0 | E16: =Assumptions!$B$110 * 'P&L'!E21 / 365 -> 6102.7397 | F16: =Assumptions!$B$110 * 'P&L'!F21 / 365 -> 19889.384 | G16: =Assumptions!$B$110 * 'P&L'!G21 / 365 -> 63635.856 | H16: =Assumptions!$B$110 * 'P&L'!H21 / 365 -> 137317.9 | I16: =Assumptions!$B$110 * 'P&L'!I21 / 365 -> 324829.32 | L16: £ | M16: DIO × COGS / 365
A17: (Increase) / decrease in inventory | C17: =-(C16 - OFFSET(C16, 0, -1)) -> 0 | D17: =-(D16 - OFFSET(D16, 0, -1)) -> 0 | E17: =-(E16 - OFFSET(E16, 0, -1)) -> -6102.7397 | F17: =-(F16 - OFFSET(F16, 0, -1)) -> -13786.644 | G17: =-(G16 - OFFSET(G16, 0, -1)) -> -43746.473 | H17: =-(H16 - OFFSET(H16, 0, -1)) -> -73682.045 | I17: =-(I16 - OFFSET(I16, 0, -1)) -> -187511.42 | L17: £
A18: Receivables (end of year) | C18: =Assumptions!$B$111 * 'P&L'!C14 / 365 -> 0 | D18: =Assumptions!$B$111 * 'P&L'!D14 / 365 -> 0 | E18: =Assumptions!$B$111 * 'P&L'!E14 / 365 -> 6590.9589 | F18: =Assumptions!$B$111 * 'P&L'!F14 / 365 -> 26097.534 | G18: =Assumptions!$B$111 * 'P&L'!G14 / 365 -> 95353.644 | H18: =Assumptions!$B$111 * 'P&L'!H14 / 365 -> 212528.1 | I18: =Assumptions!$B$111 * 'P&L'!I14 / 365 -> 490556.31 | L18: £ | M18: DSO × revenue / 365
A19: (Increase) / decrease in receivables | C19: =-(C18 - OFFSET(C18, 0, -1)) -> 0 | D19: =-(D18 - OFFSET(D18, 0, -1)) -> 0 | E19: =-(E18 - OFFSET(E18, 0, -1)) -> -6590.9589 | F19: =-(F18 - OFFSET(F18, 0, -1)) -> -19506.575 | G19: =-(G18 - OFFSET(G18, 0, -1)) -> -69256.11 | H19: =-(H18 - OFFSET(H18, 0, -1)) -> -117174.45 | I19: =-(I18 - OFFSET(I18, 0, -1)) -> -278028.21 | L19: £
A20: Payables (end of year) | C20: =Assumptions!$B$112 * ('P&L'!C21 + ('P&L'!C56 - Assumptions!C69)) / 365 -> 6164.3836 | D20: =Assumptions!$B$112 * ('P&L'!D21 + ('P&L'!D56 - Assumptions!D69)) / 365 -> 28232.877 | E20: =Assumptions!$B$112 * ('P&L'!E21 + ('P&L'!E56 - Assumptions!E69)) / 365 -> 41757.534 | F20: =Assumptions!$B$112 * ('P&L'!F21 + ('P&L'!F56 - Assumptions!F69)) / 365 -> 50522.671 | G20: =Assumptions!$B$112 * ('P&L'!G21 + ('P&L'!G56 - Assumptions!G69)) / 365 -> 96866.445 | H20: =Assumptions!$B$112 * ('P&L'!H21 + ('P&L'!H56 - Assumptions!H69)) / 365 -> 167952.38 | I20: =Assumptions!$B$112 * ('P&L'!I21 + ('P&L'!I56 - Assumptions!I69)) / 365 -> 313253.75 | L20: £ | M20: DPO × (COGS + non-payroll opex) / 365
A21: Increase / (decrease) in payables | C21: =C20 - OFFSET(C20, 0, -1) -> 6164.3836 | D21: =D20 - OFFSET(D20, 0, -1) -> 22068.493 | E21: =E20 - OFFSET(E20, 0, -1) -> 13524.658 | F21: =F20 - OFFSET(F20, 0, -1) -> 8765.137 | G21: =G20 - OFFSET(G20, 0, -1) -> 46343.774 | H21: =H20 - OFFSET(H20, 0, -1) -> 71085.939 | I21: =I20 - OFFSET(I20, 0, -1) -> 145301.37 | L21: £
A22: Deferred revenue (end of year) | C22: ='P&L'!C10 * 0.5 -> 0 | D22: ='P&L'!D10 * 0.5 -> 0 | E22: ='P&L'!E10 * 0.5 -> 13500 | F22: ='P&L'!F10 * 0.5 -> 66150 | G22: ='P&L'!G10 * 0.5 -> 167535 | H22: ='P&L'!H10 * 0.5 -> 398281.5 | I22: ='P&L'!I10 * 0.5 -> 875953.35 | L22: £ | M22: ≈ subscription revenue × 0.5 (annual prepay convention)
A23: Increase / (decrease) in deferred revenue | C23: =C22 - OFFSET(C22, 0, -1) -> 0 | D23: =D22 - OFFSET(D22, 0, -1) -> 0 | E23: =E22 - OFFSET(E22, 0, -1) -> 13500 | F23: =F22 - OFFSET(F22, 0, -1) -> 52650 | G23: =G22 - OFFSET(G22, 0, -1) -> 101385 | H23: =H22 - OFFSET(H22, 0, -1) -> 230746.5 | I23: =I22 - OFFSET(I22, 0, -1) -> 477671.85 | L23: £
A24: Total working capital change | C24: =C17 + C19 + C21 + C23 -> 6164.3836 | D24: =D17 + D19 + D21 + D23 -> 22068.493 | E24: =E17 + E19 + E21 + E23 -> 14330.959 | F24: =F17 + F19 + F21 + F23 -> 28121.918 | G24: =G17 + G19 + G21 + G23 -> 34726.192 | H24: =H17 + H19 + H21 + H23 -> 110975.94 | I24: =I17 + I19 + I21 + I23 -> 157433.59 | L24: £
A25: + Interest income on opening cash | C25: ='P&L'!C64 -> 0 | D25: ='P&L'!D64 -> 22534.784 | E25: ='P&L'!E64 -> 9514.1018 | F25: ='P&L'!F64 -> 40037.088 | G25: ='P&L'!G64 -> 14294.941 | H25: ='P&L'!H64 -> 31164.892 | I25: ='P&L'!I64 -> 14742.733 | L25: £ | M25: Mirrors P&L line; cash-effective in same year
A26: NET CASH FROM OPERATIONS | C26: =C13 + C24 + C25 -> -242340.54 | D26: =D13 + D24 + D25 -> -428022.74 | E26: =E13 + E24 + E25 -> -717567.14 | F26: =F13 + F24 + F25 -> -838071.55 | G26: =G13 + G24 + G25 -> -857668.29 | H26: =H13 + H24 + H25 -> -535405.32 | I26: =I13 + I24 + I25 -> 399506.54 | L26: £
A28: 3. INVESTING CASH FLOW
A29: Capex (cash outflow) | C29: =-Assumptions!C103 -> -6500 | D29: =-Assumptions!D103 -> -6000 | E29: =-Assumptions!E103 -> -15000 | F29: =-Assumptions!F103 -> -20000 | G29: =-Assumptions!G103 -> -30000 | H29: =-Assumptions!H103 -> -12000 | I29: =-Assumptions!I103 -> -22000 | L29: £ | M29: Linked from Assumptions capex schedule
A30: NET CASH FROM INVESTING | C30: =C29 -> -6500 | D30: =D29 -> -6000 | E30: =E29 -> -15000 | F30: =F29 -> -20000 | G30: =G29 -> -30000 | H30: =H29 -> -12000 | I30: =I29 -> -22000 | L30: £
A32: 4. FINANCING CASH FLOW
A33: Equity injections | C33: =Assumptions!C126 -> 1000000 | D33: =Assumptions!D126 -> 0 | E33: =Assumptions!E126 -> 1750000 | F33: =Assumptions!F126 -> 0 | G33: =Assumptions!G126 -> 1450000 | H33: =Assumptions!H126 -> 0 | I33: =Assumptions!I126 -> 0 | L33: £ | M33: Mechanical plug — sized to keep closing cash ≥ buffer
A34: NET CASH FROM FINANCING | C34: =C33 -> 1000000 | D34: =D33 -> 0 | E34: =E33 -> 1750000 | F34: =F33 -> 0 | G34: =G33 -> 1450000 | H34: =H33 -> 0 | I34: =I33 -> 0 | L34: £
A36: 5. CASH POSITION
A37: Net change in cash | C37: =C26 + C30 + C34 -> 751159.46 | D37: =D26 + D30 + D34 -> -434022.74 | E37: =E26 + E30 + E34 -> 1017432.9 | F37: =F26 + F30 + F34 -> -858071.55 | G37: =G26 + G30 + G34 -> 562331.71 | H37: =H26 + H30 + H34 -> -547405.32 | I37: =I26 + I30 + I34 -> 377506.54 | L37: £
A38: Opening cash | C38: =OFFSET(C38, 1, -1) -> 0 | D38: =OFFSET(D38, 1, -1) -> 751159.46 | E38: =OFFSET(E38, 1, -1) -> 317136.73 | F38: =OFFSET(F38, 1, -1) -> 1334569.6 | G38: =OFFSET(G38, 1, -1) -> 476498.03 | H38: =OFFSET(H38, 1, -1) -> 1038829.7 | I38: =OFFSET(I38, 1, -1) -> 491424.43 | L38: £
A39: Closing cash | C39: =C38 + C37 -> 751159.46 | D39: =D38 + D37 -> 317136.73 | E39: =E38 + E37 -> 1334569.6 | F39: =F38 + F37 -> 476498.03 | G39: =G38 + G37 -> 1038829.7 | H39: =H38 + H37 -> 491424.43 | I39: =I38 + I37 -> 868930.97 | L39: £
A40: Minimum cash buffer (target floor) | C40: =Assumptions!$B$127 -> 100000 | D40: =Assumptions!$B$127 -> 100000 | E40: =Assumptions!$B$127 -> 100000 | F40: =Assumptions!$B$127 -> 100000 | G40: =Assumptions!$B$127 -> 100000 | H40: =Assumptions!$B$127 -> 100000 | I40: =Assumptions!$B$127 -> 100000 | L40: £
A41: Buffer breached? (1 = closing cash below buffer) | C41: =IF(C39 < C40, 1, 0) -> 0 | D41: =IF(D39 < D40, 1, 0) -> 0 | E41: =IF(E39 < E40, 1, 0) -> 0 | F41: =IF(F39 < F40, 1, 0) -> 0 | G41: =IF(G39 < G40, 1, 0) -> 0 | H41: =IF(H39 < H40, 1, 0) -> 0 | I41: =IF(I39 < I40, 1, 0) -> 0 | L41: flag
A42: Cumulative ops + investing (excludes financing) | C42: =C26 + C30 + OFFSET(C42, 0, -1) -> -248840.54 | D42: =D26 + D30 + OFFSET(D42, 0, -1) -> -682863.27 | E42: =E26 + E30 + OFFSET(E42, 0, -1) -> -1415430.4 | F42: =F26 + F30 + OFFSET(F42, 0, -1) -> -2273502 | G42: =G26 + G30 + OFFSET(G42, 0, -1) -> -3161170.3 | H42: =H26 + H30 + OFFSET(H42, 0, -1) -> -3708575.6 | I42: =I26 + I30 + OFFSET(I42, 0, -1) -> -3331069 | L42: £ | M42: Running unfunded cash position; lowest point sets the funding floor
A44: 6. CASH FLOW SUMMARY
A45: Minimum closing-cash point over horizon | B45: =MIN(C39:I39) -> 317136.73 | L45: £ | M45: With the equity plug — must stay above the buffer
A46: Year of minimum closing cash | B46: =INDEX($C$4:$K$4, MATCH(MIN(C39:I39), C39:I39, 0)) -> Y2
A47: Peak unfunded cash trough | B47: =MIN(C42:K42) -> -3708575.6 | L47: £ | M47: Most-negative cumulative ops+investing — the gross funding need
...

Sheet Balance sheet
A1: Balance Sheet — 7-year projection (year-end)
A2: Aggregates working-capital and PP&E balances from the Cash flow / Assumptions tabs, plus cumulative share capital and retained earnings. Balance check row must be £0 every year.
A4: Year | C4: =Assumptions!C4 -> Y1 | D4: =Assumptions!D4 -> Y2 | E4: =Assumptions!E4 -> Y3 | F4: =Assumptions!F4 -> Y4 | G4: =Assumptions!G4 -> Y5 | H4: =Assumptions!H4 -> Y6 | I4: =Assumptions!I4 -> Y7
A5: Period number | C5: =Assumptions!C5 -> 1 | D5: =Assumptions!D5 -> 2 | E5: =Assumptions!E5 -> 3 | F5: =Assumptions!F5 -> 4 | G5: =Assumptions!G5 -> 5 | H5: =Assumptions!H5 -> 6 | I5: =Assumptions!I5 -> 7
A6: Phase | C6: =Assumptions!C7 -> 1 | D6: =Assumptions!D7 -> 1 | E6: =Assumptions!E7 -> 2 | F6: =Assumptions!F7 -> 2 | G6: =Assumptions!G7 -> 3 | H6: =Assumptions!H7 -> 3 | I6: =Assumptions!I7 -> 3
A8: 1. ASSETS
A9: Cash and cash equivalents | C9: ='Cash flow'!C39 -> 751159.46 | D9: ='Cash flow'!D39 -> 317136.73 | E9: ='Cash flow'!E39 -> 1334569.6 | F9: ='Cash flow'!F39 -> 476498.03 | G9: ='Cash flow'!G39 -> 1038829.7 | H9: ='Cash flow'!H39 -> 491424.43 | I9: ='Cash flow'!I39 -> 868930.97 | L9: £
A10: Accounts receivable | C10: ='Cash flow'!C18 -> 0 | D10: ='Cash flow'!D18 -> 0 | E10: ='Cash flow'!E18 -> 6590.9589 | F10: ='Cash flow'!F18 -> 26097.534 | G10: ='Cash flow'!G18 -> 95353.644 | H10: ='Cash flow'!H18 -> 212528.1 | I10: ='Cash flow'!I18 -> 490556.31 | L10: £
A11: Inventory | C11: ='Cash flow'!C16 -> 0 | D11: ='Cash flow'!D16 -> 0 | E11: ='Cash flow'!E16 -> 6102.7397 | F11: ='Cash flow'!F16 -> 19889.384 | G11: ='Cash flow'!G16 -> 63635.856 | H11: ='Cash flow'!H16 -> 137317.9 | I11: ='Cash flow'!I16 -> 324829.32 | L11: £
A12: Total current assets | C12: =SUM(C9:C11) -> 751159.46 | D12: =SUM(D9:D11) -> 317136.73 | E12: =SUM(E9:E11) -> 1347263.3 | F12: =SUM(F9:F11) -> 522484.95 | G12: =SUM(G9:G11) -> 1197819.2 | H12: =SUM(H9:H11) -> 841270.43 | I12: =SUM(I9:I11) -> 1684316.6 | L12: £
A14: PP&E (gross — cumulative capex) | C14: =Assumptions!C104 -> 6500 | D14: =Assumptions!D104 -> 12500 | E14: =Assumptions!E104 -> 27500 | F14: =Assumptions!F104 -> 47500 | G14: =Assumptions!G104 -> 77500 | H14: =Assumptions!H104 -> 89500 | I14: =Assumptions!I104 -> 111500 | L14: £
A15: Less: accumulated depreciation | C15: =-Assumptions!C106 -> -1300 | D15: =-Assumptions!D106 -> -3800 | E15: =-Assumptions!E106 -> -9300 | F15: =-Assumptions!F106 -> -18800 | G15: =-Assumptions!G106 -> -34300 | H15: =-Assumptions!H106 -> -50900 | I15: =-Assumptions!I106 -> -69442.857 | L15: £
A16: Net PP&E | C16: =C14 + C15 -> 5200 | D16: =D14 + D15 -> 8700 | E16: =E14 + E15 -> 18200 | F16: =F14 + F15 -> 28700 | G16: =G14 + G15 -> 43200 | H16: =H14 + H15 -> 38600 | I16: =I14 + I15 -> 42057.143 | L16: £
A18: TOTAL ASSETS | C18: =C12 + C16 -> 756359.46 | D18: =D12 + D16 -> 325836.73 | E18: =E12 + E16 -> 1365463.3 | F18: =F12 + F16 -> 551184.95 | G18: =G12 + G16 -> 1241019.2 | H18: =H12 + H16 -> 879870.43 | I18: =I12 + I16 -> 1726373.7 | L18: £
A20: 2. LIABILITIES
A21: Accounts payable | C21: ='Cash flow'!C20 -> 6164.3836 | D21: ='Cash flow'!D20 -> 28232.877 | E21: ='Cash flow'!E20 -> 41757.534 | F21: ='Cash flow'!F20 -> 50522.671 | G21: ='Cash flow'!G20 -> 96866.445 | H21: ='Cash flow'!H20 -> 167952.38 | I21: ='Cash flow'!I20 -> 313253.75 | L21: £
A22: Deferred revenue (annual prepay) | C22: ='Cash flow'!C22 -> 0 | D22: ='Cash flow'!D22 -> 0 | E22: ='Cash flow'!E22 -> 13500 | F22: ='Cash flow'!F22 -> 66150 | G22: ='Cash flow'!G22 -> 167535 | H22: ='Cash flow'!H22 -> 398281.5 | I22: ='Cash flow'!I22 -> 875953.35 | L22: £
A23: Total current liabilities | C23: =C21 + C22 -> 6164.3836 | D23: =D21 + D22 -> 28232.877 | E23: =E21 + E22 -> 55257.534 | F23: =F21 + F22 -> 116672.67 | G23: =G21 + G22 -> 264401.45 | H23: =H21 + H22 -> 566233.88 | I23: =I21 + I22 -> 1189207.1 | L23: £
A25: TOTAL LIABILITIES | C25: =C23 -> 6164.3836 | D25: =D23 -> 28232.877 | E25: =E23 -> 55257.534 | F25: =F23 -> 116672.67 | G25: =G23 -> 264401.45 | H25: =H23 -> 566233.88 | I25: =I23 -> 1189207.1 | L25: £
A27: 3. EQUITY
A28: Share capital (cumulative equity raised) | C28: =SUM(Assumptions!$C$126:C126) -> 1000000 | D28: =SUM(Assumptions!$C$126:D126) -> 1000000 | E28: =SUM(Assumptions!$C$126:E126) -> 2750000 | F28: =SUM(Assumptions!$C$126:F126) -> 2750000 | G28: =SUM(Assumptions!$C$126:G126) -> 4200000 | H28: =SUM(Assumptions!$C$126:H126) -> 4200000 | I28: =SUM(Assumptions!$C$126:I126) -> 4200000 | L28: £ | M28: Running sum of equity injections
A29: Retained earnings (cumulative NI) | C29: =SUM('P&L'!$C$75:C75) -> -249804.92 | D29: =SUM('P&L'!$C$75:D75) -> -702396.15 | E29: =SUM('P&L'!$C$75:E75) -> -1439794.2 | F29: =SUM('P&L'!$C$75:F75) -> -2315487.7 | G29: =SUM('P&L'!$C$75:G75) -> -3223382.2 | H29: =SUM('P&L'!$C$75:H75) -> -3886363.5 | I29: =SUM('P&L'!$C$75:I75) -> -3662833.4 | L29: £ | M29: Running sum of P&L net income
A30: TOTAL EQUITY | C30: =C28 + C29 -> 750195.08 | D30: =D28 + D29 -> 297603.85 | E30: =E28 + E29 -> 1310205.8 | F30: =F28 + F29 -> 434512.28 | G30: =G28 + G29 -> 976617.8 | H30: =H28 + H29 -> 313636.54 | I30: =I28 + I29 -> 537166.63 | L30: £
A32: 4. BALANCE CHECK
A33: Total liabilities + equity | C33: =C25 + C30 -> 756359.46 | D33: =D25 + D30 -> 325836.73 | E33: =E25 + E30 -> 1365463.3 | F33: =F25 + F30 -> 551184.95 | G33: =G25 + G30 -> 1241019.2 | H33: =H25 + H30 -> 879870.43 | I33: =I25 + I30 -> 1726373.7 | L33: £
A34: Difference (assets − L − E; should be 0) | C34: =C18 - C33 -> 0 | D34: =D18 - D33 -> 0 | E34: =E18 - E33 -> 0 | F34: =F18 - F33 -> 0 | G34: =G18 - G33 -> 0 | H34: =H18 - H33 -> 0 | I34: =I18 - I33 -> 0 | L34: £
A35: BS balanced? (1 = yes within £1 tolerance) | C35: =IF(ABS(C34) < 1, 1, 0) -> 1 | D35: =IF(ABS(D34) < 1, 1, 0) -> 1 | E35: =IF(ABS(E34) < 1, 1, 0) -> 1 | F35: =IF(ABS(F34) < 1, 1, 0) -> 1 | G35: =IF(ABS(G34) < 1, 1, 0) -> 1 | H35: =IF(ABS(H34) < 1, 1, 0) -> 1 | I35: =IF(ABS(I34) < 1, 1, 0) -> 1

Sheet Scenarios
A1: Scenarios & Sensitivity
A2: Change the scenario selector in cell B5 to flex the entire model. Active multipliers in section 3 are referenced by formulas in Assumptions and P&L. The tornado in section 5 is a linear approximation — for exact figures, toggle the selector and read the live model.
A4: 1. SCENARIO SELECTOR
A5: Active scenario (1=Base, 2=Downside, 3=Upside, 4=RegDelay, 5=Best, 6=Worst) | B5: 1
A6: Active scenario name | B6: =CHOOSE($B$5, "Base", "Downside", "Upside", "Reg Delay", "Best", "Worst") -> Base
A8: 2. SCENARIO DEFINITION TABLE (multipliers vs base + reg delay years)
A9: Driver | B9: Base | C9: Downside | D9: Upside | E9: Reg Delay | F9: Best | G9: Worst | M9: Interpretation
A10: Adoption ramp multiplier | B10: 1 | C10: 0.5 | D10: 1.3 | E10: 1 | F10: 1.2 | G10: 0.8 | M10: ch.13 Best/Worst: ±20% adoption around base
A11: BOM unit cost multiplier | B11: 1 | C11: 1.3 | D11: 0.85 | E11: 1 | F11: 0.9 | G11: 1.25 | M11: ch.13 Worst: cost-down slips, +20-30% (use 25%); Best: -10%
A12: Subscription churn multiplier | B12: 1 | C12: 1.5 | D12: 0.7 | E12: 1 | F12: 0.8 | G12: 1.5 | M12: ch.13: Best 8% (×0.8), Worst 15% (×1.5) from 10% base
A13: Headcount / payroll multiplier | B13: 1 | C13: 1.1 | D13: 0.95 | E13: 1.05 | F13: 1 | G13: 1.1 | M13: ch.13 Worst: burn +10% via payroll lever (dominant cost)
A14: Marketing spend multiplier | B14: 1 | C14: 1.2 | D14: 0.8 | E14: 1 | F14: 1 | G14: 1 | M14: ch.13 Best/Worst hold marketing flat; effect routed via payroll
A15: Regulatory & clinical multiplier | B15: 1 | C15: 1.5 | D15: 0.8 | E15: 1.4 | F15: 1 | G15: 1.2 | M15: Worst: extra NB / clinical cost from delay (+20%)
A16: Regulatory delay (years shifted) | B16: 0 | C16: 0 | D16: 0 | E16: 1 | F16: 0 | G16: 1 | M16: ch.13 Worst: 12-month MDR slip
A17: Hardware ASP multiplier | B17: 1 | C17: 1 | D17: 1 | E17: 1 | F17: 1.1 | G17: 0.875 | M17: ch.13: Best +10%, Worst -12.5% (mid of -10/-15%)
A18: Subscription ARPU multiplier | B18: 1 | C18: 1 | D18: 1 | E18: 1 | F18: 1.1 | G18: 0.875 | M18: ch.13: Best +10%, Worst -12.5% (mid of -10/-15%)
A19: 3. ACTIVE MULTIPLIERS (live values used by Assumptions and P&L)
A20: Adoption multiplier (active) | B20: =CHOOSE($B$5, $B$10, $C$10, $D$10, $E$10, $F$10, $G$10) -> 1
A21: BOM unit cost multiplier (active) | B21: =CHOOSE($B$5, $B$11, $C$11, $D$11, $E$11, $F$11, $G$11) -> 1
A22: Subscription churn multiplier (active) | B22: =CHOOSE($B$5, $B$12, $C$12, $D$12, $E$12, $F$12, $G$12) -> 1
A23: Headcount / payroll multiplier (active) | B23: =CHOOSE($B$5, $B$13, $C$13, $D$13, $E$13, $F$13, $G$13) -> 1
A24: Marketing spend multiplier (active) | B24: =CHOOSE($B$5, $B$14, $C$14, $D$14, $E$14, $F$14, $G$14) -> 1
A25: Regulatory & clinical multiplier (active) | B25: =CHOOSE($B$5, $B$15, $C$15, $D$15, $E$15, $F$15, $G$15) -> 1
A26: Regulatory delay (years, active) | B26: =CHOOSE($B$5, $B$16, $C$16, $D$16, $E$16, $F$16, $G$16) -> 0
A27: Hardware ASP multiplier (active) | B27: =CHOOSE($B$5, $B$17, $C$17, $D$17, $E$17, $F$17, $G$17) -> 1
A28: Subscription ARPU multiplier (active) | B28: =CHOOSE($B$5, $B$18, $C$18, $D$18, $E$18, $F$18, $G$18) -> 1
A30: 4. ACTIVE SCENARIO HEADLINE OUTPUTS (live, recomputes when selector changes)
A31: Active scenario name | B31: =$B$6 -> Base
A32: Y7 total revenue | B32: ='P&L'!I14 -> 3978956.7
A33: Y7 gross profit | B33: ='P&L'!I23 -> 2398120.7
A34: Y7 EBITDA | B34: ='P&L'!I58 -> 149150.7
A35: Y7 net income | B35: ='P&L'!I75 -> 223530.09
A36: Y7 closing cash | B36: ='Cash flow'!I39 -> 868930.97
A37: Peak unfunded cash trough | B37: ='Cash flow'!B47 -> -3708575.6
A38: First year of positive operating cash flow | B38: ='Cash flow'!B52 -> Y7
A39: Total equity raised through Y7 | B39: ='Cash flow'!B49 -> 4200000
A41: 5. APPROXIMATE TORNADO SENSITIVITY (Y7 EBITDA delta vs base, linear approx)
A42: Driver | B42: Down delta | C42: Up delta | D42: Magnitude | M42: Approximation basis
A43: Adoption ramp ±20% | B43: =-0.2 * 'P&L'!I23 -> -479624.14 | C43: =0.2 * 'P&L'!I23 -> 479624.14 | D43: =MAX(ABS(B43), ABS(C43)) -> 479624.14 | M43: ±20% × Y7 gross profit (revenue scales linearly with adoption)
A44: Blended ARPU ±15% | B44: =-0.15 * 'P&L'!I10 * 0.85 -> -223368.1 | C44: =0.15 * 'P&L'!I10 * 0.85 -> 223368.1 | D44: =MAX(ABS(B44), ABS(C44)) -> 223368.1 | M44: ±15% × Y7 sub revenue × (1 - sub COGS rate); subscription pricing lever
...
